<?xml version="1.0"?>
<robot xmlns:xacro="http://www.ros.org/wiki/xacro">

    <xacro:include filename="inertial_macros.xacro"/>

    <material name="white">
        <color rgba="1 1 1 1"/>
    </material>
    
    <material name="orange">
        <color rgba="1 0.3 0.1 1"/>
    </material>

    <material name="blue">
        <color rgba="0.2 0.2 1 1"/>
    </material>

    <material name="black">
        <color rgba="0 0 0 1"/>
    </material>

    <material name="red">
        <color rgba="1 0 0 1"/>
    </material>

    <material name="silver">
        <color rgba="0.7725490196078432 0.788235294117647 0.7803921568627451 1.0"/>    
    </material>

    <!-- BASE LINK -->

    <link name="base_link">

    </link>
    
    <!-- BASE_FOOTPRINT LINK-->

    <joint name="base_footprint_joint" type="fixed">
        <parent link="base_link"/>
        <child link="base_footprint"/>
        <origin xyz="0 0 0" rpy="0 0 0"/>
    </joint>

    <link name="base_footprint">
    </link>

    <!-- BOTTOM BOX LINK -->

    <joint name="bottom_box_joint" type="fixed">
        <parent link="base_link"/>
        <child link="bottom_box"/>
        <origin xyz="-0.15 0 0"/>
    </joint>

    <link name="bottom_box">
        <visual>
            <origin xyz="0.15 0 0.0375"/>
            <geometry>
                <box size="0.3 0.3 0.15"/>
            </geometry>
            <material name ="white"/>
        </visual>
        <collision>
            <origin xyz="0.15 0 0.0375"/>
            <geometry>
                <box size="0.3 0.3 0.15"/>
            </geometry>
        </collision>
        <xacro:inertial_box mass="0.5" x="0.3" y="0.3" z="0.15">
            <origin xyz="0.15 0 0.0375" rpy="0 0 0"/>
        </xacro:inertial_box>
    </link>

    <gazebo reference="bottom_box">
        <material>Gazebo/White</material>
    </gazebo>

    <!-- MIDDLE BOX LINK -->

    <joint name="middle_box_joint" type="fixed">
        <parent link="base_link"/>
        <child link="middle_box"/>
        <origin xyz="0 0 0.15"/>
    </joint>

    <link name="middle_box">
        <visual>
            <origin xyz="0 0 0.15"/>
            <geometry>
                <box size="0.15 0.15 0.0375"/>
            </geometry>
            <material name ="white"/>
        </visual>
        <collision>
            <origin xyz="0 0 0.15"/>
            <geometry>
                <box size="0.15 0.15 0.0375"/>
            </geometry>
        </collision>
        <xacro:inertial_box mass="0.5" x="0.15" y="0.15" z="0.0375">
            <origin xyz="0 0 0.15" rpy="0 0 0"/>
        </xacro:inertial_box>
    </link>

    <gazebo reference="middle_box">
        <material>Gazebo/White</material>
    </gazebo>

    <!-- UPPER BOX LINK -->

    <joint name="upper_box_joint" type="fixed">
        <parent link="base_link"/>
        <child link="upper"/>
        <origin xyz="-0.15 0 0"/>
    </joint>

    <link name="upper_box">
        <visual>
            <origin xyz="0 0 0.1875"/>
            <geometry>
                <box size="0.3 0.3 0.3"/>
            </geometry>
            <material name ="white"/>
        </visual>
        <collision>
            <origin xyz="0.15 0 0.1875"/>
            <geometry>
                <box size="0.3 0.3 0.3"/>
            </geometry>
        </collision>
        <xacro:inertial_box mass="0.5" x="0.3" y="0.3" z="0.3">
            <origin xyz="0 0 0.1875" rpy="0 0 0"/>
        </xacro:inertial_box>
    </link>

    <gazebo reference="upper_box">
        <material>Gazebo/White</material>
    </gazebo>

    <!-- OUTER CASE LINK-->

  <!--  <joint name="outer_case_joint" type="fixed">
        <parent link="base_link"/>
        <child link="outer_case"/>
        <origin xyz="0 0 0"/> <!-- Adjusted origin to align properly -->
    </joint>

    <link name="outer_case">
        <!-- Visual representation of the outer case (box shape) -->
        <visual>
            <origin xyz="0 0 0"/>
            <geometry>
                <box size="0.6 0.75 0.05"/> <!-- Adjusted size to fit caster wheels inside corners -->
            </geometry>
            <material name="orange"/>
        </visual>

        <!-- Collision representation of the outer case (box shape) -->
        <collision>
            <origin xyz="0 0 0"/>
            <geometry>
                <box size="0.6 0.75 0.05"/> <!-- Adjusted size to fit caster wheels inside corners -->
            </geometry>
        </collision>

        <!-- Inertial properties of the box -->
        <xacro:inertial_box mass="2.0" x="0.6" y="0.75" z="0.05">
            <origin xyz="0 0 0" rpy="0 0 0"/>
        </xacro:inertial_box>
    </link>

    <gazebo reference="outer_case">
        <material>Gazebo/Orange</material>
    </gazebo>

    <!-- LEFT WHEEL LINK -->
    <joint name="left_wheel_joint" type="continuous">
        <parent link="base_link"/>
        <child link="left_wheel"/>
        <origin xyz="0 0.175 0" rpy="-${pi/2} 0 0"/>
        <axis xyz="0 0 1"/>
    </joint>

    <link name="left_wheel">
        <visual>
            <geometry>
                <cylinder radius="0.05" length="0.04"/>
            </geometry>
            <material name="blue"/>
        </visual>
        <collision>
            <geometry>
                <cylinder radius="0.05" length="0.04"/>
            </geometry>
        </collision>
        <xacro:inertial_cylinder mass="0.1" length="0.04" radius="0.05">
            <origin xyz="0 0 0 " rpy="0 0 0"/>
        </xacro:inertial_cylinder>
    </link>
    <gazebo reference="left_wheel">
        <material>Gazebo/Blue</material>
    </gazebo>

    <!-- RIGHT WHEEL LINK -->
    <joint name="right_wheel_joint" type="continuous">
        <parent link="base_link"/>
        <child link="right_wheel"/>
        <origin xyz="0 -0.175 0" rpy="${pi/2} 0 0"/>
        <axis xyz="0 0 -1"/>
    </joint>

    <link name="right_wheel">
        <visual>
            <geometry>
                <cylinder radius="0.05" length="0.04"/>
            </geometry>
            <material name="blue"/>
        </visual>
        <collision>
            <geometry>
                <cylinder radius="0.05" length="0.04"/>
            </geometry>robot urdf stl files
        </collision>
        <xacro:inertial_cylinder mass="0.1" length="0.04" radius="0.05">
            <origin xyz="0 0 0 " rpy="0 0 0"/>robot urdf stl files
        </xacro:inertial_cylinder>
    </link>
    <gazebo reference="right_wheel">
        <material>Gazebo/Blue</material>
    </gazebo>

    <!-- CASTER WHEELS -->

    <!-- Front Left Caster Wheel -->
    <joint name="caster_wheel_front_left_joint" type="fixed">
        <parent link="base_link"/>
        <child link="caster_wheel_front_left"/>
        <origin xyz="0.25 0.25 0"/>
    </joint>

    <link name="caster_wheel_front_left">
        <visual>
            <geometry>
                <sphere radius="0.05"/>
            </geometry>
            <material name="white"/>
        </visual>
        <collision>
            <geometry>
                <sphere radius="0.05"/>
            </geometry>
        </collision>
        <xacro:inertial_sphere mass="0.1" radius="0.05">
            <origin xyz="0 0 0" rpy="0 0 0"/>
        </xacro:inertial_sphere>
    </link>

    <gazebo reference="caster_wheel_front_left">
        <material>Gazebo/White</material>
        <mu1 value="0.001"/>
        <mu2 value="0.001"/>
    </gazebo>

    <!-- Front Right Caster Wheel -->
    <joint name="caster_wheel_front_right_joint" type="fixed">
        <parent link="base_link"/>
        <child link="caster_wheel_front_right"/>
        <origin xyz="0.25 -0.25 0"/>
    </joint>

    <link name="caster_wheel_front_right">
        <visual>
            <geometry>
                <sphere radius="0.05"/>
            </geometry>
            <material name="white"/>
        </visual>
        <collision>
            <geometry>
                <sphere radius="0.05"/>
            </geometry>
        </collision>
        <xacro:inertial_sphere mass="0.1" radius="0.05">
            <origin xyz="0 0 0" rpy="0 0 0"/>
        </xacro:inertial_sphere>
    </link>

    <gazebo reference="caster_wheel_front_right">
        <material>Gazebo/White</material>
        <mu1 value="0.001"/>
        <mu2 value="0.001"/>
    </gazebo>

    <!-- Back Right Caster Wheel -->
    <joint name="caster_wheel_back_right_joint" type="fixed">
        <parent link="base_link"/>
        <child link="caster_wheel_back_right"/>
        <origin xyz="-0.25 -0.25 0"/>
    </joint>

    <link name="caster_wheel_back_right">
        <visual>
            <geometry>
                <sphere radius="0.05"/>
            </geometry>
            <material name="white"/>
        </visual>
        <collision>
            <geometry>
                <sphere radius="0.05"/>
            </geometry>
        </collision>
        <xacro:inertial_sphere mass="0.1" radius="0.05">
            <origin xyz="0 0 0" rpy="0 0 0"/>
        </xacro:inertial_sphere>
    </link>

    <gazebo reference="caster_wheel_back_right">
        <material>Gazebo/White</material>
        <mu1 value="0.001"/>
        <mu2 value="0.001"/>
    </gazebo>

    <!-- Back Left Caster Wheel -->
    <joint name="caster_wheel_back_left_joint" type="fixed">
        <parent link="base_link"/>
        <child link="caster_wheel_back_left"/>
        <origin xyz="-0.25 0.25 0"/>
    </joint>

    <link name="caster_wheel_back_left">
        <visual>
            <geometry>
                <sphere radius="0.05"/>
            </geometry>
            <material name="white"/>
        </visual>
        <collision>
            <geometry>
                <sphere radius="0.05"/>
            </geometry>
        </collision>
        <xacro:inertial_sphere mass="0.1" radius="0.05">
            <origin xyz="0 0 0" rpy="0 0 0"/>
        </xacro:inertial_sphere>
    </link>

    <gazebo reference="caster_wheel_back_left">
        <material>Gazebo/White</material>
        <mu1 value="0.001"/>
        <mu2 value="0.001"/>
    </gazebo>

</robot>-->